Workbook
Name bu42019._1: Sheet3!$H$1:$L$84
Name BU42025.: Sheet4!$A$1:$F$88
Name BUpDes2018.: Sheet3!$A$1:$E$84

Sheet Sheet1
J6: TRIWULAN IV 2015 | R6: TRIWULAN I 2016 | Z6: TRIWULAN II 2016 | AL6: TRIWULAN III 2016 | AU6: TRIWULAN IV 2016 | BD6: TRIWULAN I 2017 | BN6: TRIWULAN II 2017 | BX6: TRIWULAN III 2017 | CH6: TRIWULAN IV 2017 | CR6: TRIWULAN I 2018 | DB6: TRIWULAN 2 2018 | DL6: TRIWULAN 3 2018 | DV6: TRIWULAN 4 2018 | EF6: TRIWULAN 1 2019 | EP6: Triwulan 2 2019 | EZ6: Triwulan 3 2019 | FJ6: Triwulan 4 2019 | FT6: Triwulan 1 2020 | GD6: Triwulan 2 2020 | GN6: Triwulan 3 2020 | GX6: Triwulan 4 2020 | HI6: Triwulan 1 2021 | HS6: Triwulan 2 2021 | IC6: Triwulan 3 2021 | IM6: Triwulan 4 2021 | IW6: Triwulan 1 2022 | JG6: Triwulan 2 2022 | JQ6: Triwulan 3 2022 | KA6: Triwulan 4 2022 | KK6: Triwulan 1 2023 | KU6: Triwulan 2 2023 | LE6: Triwulan 3 2023 | LO6: Triwulan 4 2023 | LY6: Triwulan 1 2024 | MI6: Triwulan 2 2024 | MS6: Triwulan 3 2024 | NC6: Triwulan 4 2024 | NM6: Triwulan 1 2025 | NW6: Triwulan 2 2025 | OG6: Triwulan 3 2025 | OQ6: Triwulan 4 2025
K7: MWH | L7: SUSUT BAKAR | N7: MWD | O7: Sisa (gram) | S7: MWH | T7: SUSUT BAKAR | V7: MWD | W7: Sisa (gram) | AA7: MWH | AB7: SUSUT BAKAR | AD7: MWD | AE7: Sisa (gram) | AM7: MWH | AN7: SUSUT BAKAR | AP7: MWD | AQ7: Sisa (gram) | AV7: MWH | AW7: SUSUT BAKAR | AY7: MWD | AZ7: Sisa (gram) | BE7: MWH | BF7: SUSUT BAKAR | BH7: MWD | BI7: Sisa (gram) | BO7: MWH | BP7: SUSUT BAKAR | BR7: MWD | BS7: Sisa (gram) | BY7: MWH | BZ7: SUSUT BAKAR | CB7: MWD | CC7: Sisa (gram) | CI7: MWH | CJ7: SUSUT BAKAR | CL7: MWD | CM7: Sisa (gram) | CR7: No Elemen | CS7: MWH | CT7: SUSUT BAKAR | CV7: MWD | CW7: Sisa (gram) | DB7: No Elemen | DC7: MWH | DD7: SUSUT BAKAR | DF7: MWD | DG7: Sisa (gram) | DL7: No Elemen | DM7: MWH | DN7: SUSUT BAKAR | DP7: MWD | DQ7: Sisa (gram) | DV7: No Elemen | DW7: MWH | DX7: SUSUT BAKAR | DZ7: MWD | EA7: Sisa (gram) | EF7: No Elemen | EG7: MWH | EH7: SUSUT BAKAR | EJ7: MWD | EK7: Sisa (gram) | EP7: No Elemen | EQ7: MWH | ER7: SUSUT BAKAR | ET7: MWD | EU7: Sisa (g) | EZ7: No Elemen | FA7: MWH | FB7: SUSUT BAKAR | FD7: MWD | FE7: Sisa (g) | FJ7: No Elemen | FK7: MWH | FL7: SUSUT BAKAR | FN7: MWD | FO7: Sisa (g) | FT7: No Elemen | FU7: MWH | FV7: SUSUT BAKAR | FX7: MWD | FY7: Sisa (g) | GD7: No Elemen | GE7: MWH | GF7: SUSUT BAKAR | GH7: MWD | GI7: Sisa (g) | GN7: No Elemen | GO7: MWH | GP7: SUSUT BAKAR | GR7: MWD | GS7: Sisa (g) | GX7: No Elemen | GY7: MWH | GZ7: SUSUT BAKAR | HB7: MWD | HC7: Sisa (g) | HI7: No Elemen | HJ7: MWH | HK7: SUSUT BAKAR | HM7: MWD | HN7: Sisa (g) | HS7: No Elemen | HT7: MWH | HU7: SUSUT BAKAR | HW7: MWD | HX7: Sisa (g) | IC7: No Elemen | ID7: MWH | IE7: SUSUT BAKAR | IG7: MWD | IH7: Sisa (g) | IM7: No Elemen | IN7: MWH | IO7: SUSUT BAKAR | IQ7: MWD | IR7: Sisa (g) | IW7: No Elemen | IX7: MWH | IY7: SUSUT BAKAR | JA7: MWD | JB7: Sisa (g) | JG7: No Elemen | JH7: MWH | JI7: SUSUT BAKAR | JK7: MWD | JL7: Sisa (g) | JQ7: No Elemen | JR7: MWH | JS7: SUSUT BAKAR | JU7: MWD | JV7: Sisa (g) | KA7: No Elemen | KB7: MWH | KC7: SUSUT BAKAR | KE7: MWD | KF7: Sisa (g) | KK7: No Elemen | KL7: MWH | KM7: SUSUT BAKAR | KO7: MWD | KP7: Sisa (g) | KU7: No Elemen | KV7: MWH | KW7: SUSUT BAKAR | KY7: MWD | KZ7: Sisa (g) | LE7: No Elemen | LF7: MWH | LG7: SUSUT BAKAR | LI7: MWD | LJ7: Sisa (g) | LO7: No Elemen | LP7: MWH | LQ7: SUSUT BAKAR | LS7: MWD | LT7: Sisa (g) | LY7: No Elemen | LZ7: MWH | MA7: SUSUT BAKAR | MC7: MWD | MD7: Sisa (g) | MI7: No Elemen | MJ7: MWH | MK7: SUSUT BAKAR | MM7: MWD | MN7: Sisa (g) | MS7: No Elemen | MT7: MWH | MU7: SUSUT BAKAR | MW7: MWD | MX7: Sisa (g) | NC7: No Elemen | ND7: MWH | NE7: SUSUT BAKAR | NG7: MWD | NH7: Sisa (g) | NM7: No Elemen | NN7: MWH | NO7: SUSUT BAKAR | NQ7: MWD | NR7: Sisa (g) | NW7: No Elemen | NX7: MWH | NY7: SUSUT BAKAR | OA7: MWD | OB7: Sisa (g) | OG7: No Elemen | OH7: MWH | OI7: SUSUT BAKAR | OK7: MWD | OL7: Sisa (g) | OQ7: No Elemen | OR7: MWH | OS7: SUSUT BAKAR | OU7: MWD | OV7: Sisa (g)
L8: % U-235 | M8: (g) U-235 | T8: % U-235 | U8: (g) U-235 | AB8: % U-235 | AC8: (g) U-235 | AN8: % U-235 | AO8: (g) U-235 | AW8: % U-235 | AX8: (g) U-235 | BF8: % U-235 | BG8: (g) U-235 | BP8: % U-235 | BQ8: (g) U-235 | BZ8: % U-235 | CA8: (g) U-235 | CJ8: % U-235 | CK8: (g) U-235 | CT8: % U-235 | CU8: (g) U-235 | DD8: % U-235 | DE8: (g) U-235 | DN8: % U-235 | DO8: (g) U-235 | DX8: % U-235 | DY8: (g) U-235 | EH8: % U-235 | EI8: (g) U-235 | ER8: % U-235 | ES8: (g) U-235 | FB8: % U-235 | FC8: (g) U-235 | FL8: % U-235 | FM8: (g) U-235 | FV8: % U-235 | FW8: (g) U-235 | GF8: % U-235 | GG8: (g) U-235 | GP8: % U-235 | GQ8: (g) U-235 | GZ8: % U-235 | HA8: (g) U-235 | HK8: % U-235 | HL8: (g) U-235 | HU8: % U-235 | HV8: (g) U-235 | IE8: % U-235 | IF8: (g) U-235 | IO8: % U-235 | IP8: (g) U-235 | IY8: % U-235 | IZ8: (g) U-235 | JI8: % U-235 | JJ8: (g) U-235 | JS8: % U-235 | JT8: (g) U-235 | KC8: % U-235 | KD8: (g) U-235 | KM8: % U-235 | KN8: (g) U-235 | KW8: % U-235 | KX8: (g) U-235 | LG8: % U-235 | LH8: (g) U-235 | LQ8: % U-235 | LR8: (g) U-235 | MA8: % U-235 | MB8: (g) U-235 | MK8: % U-235 | ML8: (g) U-235 | MU8: % U-235 | MV8: (g) U-235 | NE8: % U-235 | NF8: (g) U-235 | NO8: % U-235 | NP8: (g) U-235 | NY8: % U-235 | NZ8: (g) U-235 | OI8: % U-235 | OJ8: (g) U-235 | OS8: % U-235 | OT8: (g) U-235
A9: 1 | B9: 9884 | C9: A | D9: 37.41 | J9: 9884 | K9: 0 | L9: 0 | M9: 0 | N9: 0 | R9: 9884 | S9: 0 | T9: 0 | U9: 0 | V9: 0 | Z9: 9884 | AA9: 0 | AB9: 0 | AC9: 0 | AD9: 0 | AG9: 1 | AH9: 9884 | AI9: A | AJ9: 37.41 | AL9: 9884 | AM9: 0 | AN9: 0 | AO9: 0 | AP9: =AM9/24 -> 0 | AU9: 9884 | AV9: 0 | AW9: 0 | AX9: 0 | AY9: =AV9/24 -> 0 | BD9: 9884 | BE9: 0 | BF9: 0 | BG9: 0 | BH9: =BE9/24 -> 0 | BN9: 9884 | BO9: 0 | BP9: 0 | BQ9: 0 | BR9: =BO9/24 -> 0 | BX9: 9884 | BY9: 0 | BZ9: 0 | CA9: 0 | CB9: =BY9/24 -> 0 | CH9: 9884 | CI9: 0 | CJ9: 0 | CK9: 0 | CL9: =CI9/24 -> 0 | CR9: 9884 | CS9: 0 | CT9: 0 | CU9: 0 | CV9: =CS9/24 -> 0 | DB9: 9884 | DC9: 0 | DD9: 0 | DE9: 0 | DF9: =DC9/24 -> 0 | DL9: 9884 | DM9: 0 | DN9: 0 | DO9: 0 | DP9: =DM9/24 -> 0 | DV9: 9884 | DW9: 0 | DX9: 0 | DY9: 0 | DZ9: =DW9/24 -> 0 | EF9: 9884 | EG9: 0 | EH9: 0 | EI9: 0 | EJ9: =EG9/24 -> 0 | EP9: 9884 | EQ9: 0 | ER9: 0 | ES9: 0 | ET9: =EQ9/24 -> 0 | EZ9: 9884 | FA9: 0 | FB9: 0 | FC9: 0 | FD9: =FA9/24 -> 0 | FJ9: 9884 | FK9: 0 | FL9: 0 | FM9: 0 | FN9: =FK9/24 -> 0 | FT9: 9884 | FU9: 0 | FV9: 0 | FW9: 0 | FX9: =FU9/24 -> 0 | GD9: 9884 | GE9: 0 | GF9: 0 | GG9: 0 | GH9: =GE9/24 -> 0 | GN9: 9884 | GO9: 0 | GP9: 0 | GQ9: 0 | GR9: =GO9/24 -> 0 | GX9: 9884 | GY9: =VLOOKUP(GX9,Sheet3!$AJ$7:$AN$83,2,0) -> 0 | GZ9: =VLOOKUP(GX9,Sheet3!$AJ$7:$AN$83,2,0) -> 0 | HA9: =VLOOKUP(GX9,Sheet3!$AJ$7:$AN$83,4,0) -> 0 | HB9: =GY9/24 -> 0 | HI9: 9884 | HJ9: =VLOOKUP(HI9,Sheet3!$AQ$7:$AU$83,2,0) -> 0 | HK9: =VLOOKUP(HI9,Sheet3!$AQ$7:$AU$83,3,0) -> 0 | HL9: =VLOOKUP(HI9,Sheet3!$AQ$7:$AV$83,4,0) -> 0 | HM9: =HJ9/24 -> 0 | HS9: 9884 | HT9: 0 | HU9: 0 | HV9: 0 | HW9: =HT9/24 -> 0 | IC9: 9884 | ID9: 0 | IE9: 0 | IF9: 0 | IG9: =ID9/24 -> 0 | IM9: 9884 | IN9: 0 | IO9: 0 | IP9: 0 | IQ9: =IN9/24 -> 0 | IW9: 9884 | IX9: 0 | IY9: 0 | IZ9: 0 | JA9: =IX9/24 -> 0 | JG9: 9884 | JH9: 0 | JI9: 0 | JJ9: 0 | JK9: =JH9/24 -> 0 | JQ9: 9884 | JR9: 0 | JS9: 0 | JT9: 0 | JU9: =JR9/24 -> 0 | KA9: 9884 | KB9: 0 | KC9: 0 | KD9: 0 | KE9: =KB9/24 -> 0 | KK9: 9884 | KL9: 0 | KM9: 0 | KN9: 0 | KO9: =KL9/24 -> 0 | KU9: 9884 | KV9: 0 | KW9: 0 | KX9: 0 | KY9: =KV9/24 -> 0 | LE9: 9884 | LF9: 0 | LG9: 0 | LH9: 0 | LI9: =LF9/24 -> 0 | LO9: 9884 | LP9: 0 | LQ9: 0 | LR9: 0 | LS9: =LP9/24 -> 0 | LY9: 9884 | LZ9: 0 | MA9: 0 | MB9: 0 | MC9: =LZ9/24 -> 0 | MI9: 9884 | MJ9: 0 | MK9: 0 | ML9: 0 | MM9: =MJ9/24 -> 0 | MS9: 9884 | MT9: 0 | MU9: 0 | MV9: 0 | MW9: =MT9/24 -> 0 | NC9: 9884 | ND9: 0 | NE9: 0 | NF9: 0 | NG9: =ND9/24 -> 0 | NM9: 9884 | NN9: 0 | NO9: 0 | NP9: 0 | NQ9: =NN9/24 -> 0 | NW9: 9884 | NX9: 0 | NY9: 0 | NZ9: 0 | OA9: =NX9/24 -> 0 | OG9: 9884 | OH9: 0 | OI9: 0 | OJ9: 0 | OK9: =OH9/24 -> 0 | OQ9: 9884 | OR9: 0 | OS9: 0 | OT9: 0 | OU9: =OR9/24 -> 0
A10: 2 | B10: 10005 | C10: A | D10: 38.08 | J10: 10005 | K10: 0 | L10: 0 | M10: 0 | N10: 0 | R10: 10005 | S10: 0 | T10: 0 | U10: 0 | V10: 0 | Z10: 10005 | AA10: 0 | AB10: 0 | AC10: 0 | AD10: 0 | AG10: 2 | AH10: 10005 | AI10: A | AJ10: 38.08 | AL10: 10005 | AM10: 0 | AN10: 0 | AO10: 0 | AP10: =AM10/24 -> 0 | AU10: 10005 | AV10: 0 | AW10: 0 | AX10: 0 | AY10: =AV10/24 -> 0 | BD10: 10005 | BE10: 0 | BF10: 0 | BG10: 0 | BH10: =BE10/24 -> 0 | BN10: 10005 | BO10: 0 | BP10: 0 | BQ10: 0 | BR10: =BO10/24 -> 0 | BX10: 10005 | BY10: 0 | BZ10: 0 | CA10: 0 | CB10: =BY10/24 -> 0 | CH10: 10005 | CI10: 0 | CJ10: 0 | CK10: 0 | CL10: =CI10/24 -> 0 | CR10: 10005 | CS10: 0 | CT10: 0 | CU10: 0 | CV10: =CS10/24 -> 0 | DB10: 10005 | DC10: 0 | DD10: 0 | DE10: 0 | DF10: =DC10/24 -> 0 | DL10: 10005 | DM10: 0 | DN10: 0 | DO10: 0 | DP10: =DM10/24 -> 0 | DV10: 10005 | DW10: 0 | DX10: 0 | DY10: 0 | DZ10: =DW10/24 -> 0 | EF10: 10005 | EG10: 0 | EH10: 0 | EI10: 0 | EJ10: =EG10/24 -> 0 | EP10: 10005 | EQ10: 0 | ER10: 0 | ES10: 0 | ET10: =EQ10/24 -> 0 | EZ10: 10005 | FA10: 0 | FB10: 0 | FC10: 0 | FD10: =FA10/24 -> 0 | FJ10: 10005 | FK10: 0 | FL10: 0 | FM10: 0 | FN10: =FK10/24 -> 0 | FT10: 10005 | FU10: 0 | FV10: 0 | FW10: 0 | FX10: =FU10/24 -> 0 | GD10: 10005 | GE10: 0 | GF10: 0 | GG10: 0 | GH10: =GE10/24 -> 0 | GN10: 10005 | GO10: 0 | GP10: 0 | GQ10: 0 | GR10: =GO10/24 -> 0 | GX10: 10005 | GY10: =VLOOKUP(GX10,Sheet3!$AJ$7:$AN$83,2,0) -> 0 | GZ10: =VLOOKUP(GX10,Sheet3!$AJ$7:$AN$83,3,0) -> 0 | HA10: =VLOOKUP(GX10,Sheet3!$AJ$7:$AN$83,4,0) -> 0 | HB10: =GY10/24 -> 0 | HI10: 10005 | HJ10: =VLOOKUP(HI10,Sheet3!$AQ$7:$AU$83,2,0) -> 0 | HK10: =VLOOKUP(HI10,Sheet3!$AQ$7:$AU$83,3,0) -> 0 | HL10: =VLOOKUP(HI10,Sheet3!$AQ$7:$AV$83,4,0) -> 0 | HM10: =HJ10/24 -> 0 | HS10: 10005 | HT10: 0 | HU10: 0 | HV10: 0 | HW10: =HT10/24 -> 0 | IC10: 10005 | ID10: 0 | IE10: 0 | IF10: 0 | IG10: =ID10/24 -> 0 | IM10: 10005 | IN10: 0 | IO10: 0 | IP10: 0 | IQ10: =IN10/24 -> 0 | IW10: 10005 | IX10: 0 | IY10: 0 | IZ10: 0 | JA10: =IX10/24 -> 0 | JG10: 10005 | JH10: 0 | JI10: 0 | JJ10: 0 | JK10: =JH10/24 -> 0 | JQ10: 10005 | JR10: 0 | JS10: 0 | JT10: 0 | JU10: =JR10/24 -> 0 | KA10: 10005 | KB10: 0 | KC10: 0 | KD10: 0 | KE10: =KB10/24 -> 0 | KK10: 10005 | KL10: 0 | KM10: 0 | KN10: 0 | KO10: =KL10/24 -> 0 | KU10: 10005 | KV10: 0 | KW10: 0 | KX10: 0 | KY10: =KV10/24 -> 0 | LE10: 10005 | LF10: 0 | LG10: 0 | LH10: 0 | LI10: =LF10/24 -> 0 | LO10: 10005 | LP10: 0 | LQ10: 0 | LR10: 0 | LS10: =LP10/24 -> 0 | LY10: 10005 | LZ10: 0 | MA10: 0 | MB10: 0 | MC10: =LZ10/24 -> 0 | MI10: 10005 | MJ10: 0 | MK10: 0 | ML10: 0 | MM10: =MJ10/24 -> 0 | MS10: 10005 | MT10: 0 | MU10: 0 | MV10: 0 | MW10: =MT10/24 -> 0 | NC10: 10005 | ND10: 0 | NE10: 0 | NF10: 0 | NG10: =ND10/24 -> 0 | NM10: 10005 | NN10: 0 | NO10: 0 | NP10: 0 | NQ10: =NN10/24 -> 0 | NW10: 10005 | NX10: 0 | NY10: 0 | NZ10: 0 | OA10: =NX10/24 -> 0 | OG10: 10005 | OH10: 0 | OI10: 0 | OJ10: 0 | OK10: =OH10/24 -> 0 | OQ10: 10005 | OR10: 0 | OS10: 0 | OT10: 0 | OU10: =OR10/24 -> 0
A11: 3 | B11: 9883 | C11: B | D11: 37.46 | J11: 9883 | K11: 15.7443 | L11: 2.1098 | M11: 0.8038 | N11: =K11/24 -> 0.6560125 | O11: =D11-M11 -> 36.6562 | R11: 9883 | S11: 15.8393 | T11: 2.1225 | U11: 0.8087 | V11: =S11/24 -> 0.65997083 | W11: =D11-U11 -> 36.6513 | Z11: 9883 | AA11: 16.073 | AB11: 2.1538 | AC11: 0.8206 | AD11: =AA11/24 -> 0.66970833 | AE11: =D11-AC11 -> 36.6394 | AG11: 3 | AH11: 9883 | AI11: B | AJ11: 37.46 | AL11: 9883 | AM11: 16.3254 | AN11: 2.1877 | AO11: 0.8335 | AP11: =AM11/24 -> 0.680225 | AQ11: =AJ11-AO11 -> 36.6265 | AU11: 9883 | AV11: 16.4327 | AW11: 2.202 | AX11: 0.839 | AY11: =AV11/24 -> 0.68469583 | AZ11: =AJ11-AX11 -> 36.621 | BA11: =AVERAGE(AZ11:AZ81) -> 37.149207 | BD11: 9883 | BE11: 16.4449 | BF11: 2.2037 | BG11: 0.8396 | BH11: =BE11/24 -> 0.68520417 | BI11: =AJ11-BG11 -> 36.6204 | BN11: 9883 | BO11: 16.4902 | BP11: 2.2098 | BQ11: 0.8419 | BR11: =BO11/24 -> 0.68709167 | BS11: =AJ11-BQ11 -> 36.6181 | BX11: 9883 | BY11: 16.5794 | BZ11: 2.2217 | CA11: 0.8465 | CB11: =BY11/24 -> 0.69080833 | CC11: =AJ11-CA11 -> 36.6135 | CG11: 1 | CH11: 9883 | CI11: 16.6561 | CJ11: 2.232 | CK11: 0.8504 | CL11: =CI11/24 -> 0.69400417 | CM11: =AJ11-CK11 -> 36.6096 | CQ11: 1 | CR11: 9883 | CS11: 16.7526 | CT11: 2.2449 | CU11: 0.8553 | CV11: =CS11/24 -> 0.698025 | CW11: =AJ11-CU11 -> 36.6047 | DA11: 1 | DB11: 9883 | DC11: 16.7621 | DD11: 2.2462 | DE11: 0.8558 | DF11: =DC11/24 -> 0.69842083 | DG11: =AJ11-DE11 -> 36.6042 | DK11: 1 | DL11: 9883 | DM11: 16.8722 | DN11: 2.2609 | DO11: 0.8614 | DP11: =DM11/24 -> 0.70300833 | DQ11: =AJ11-DO11 -> 36.5986 | DS11: =DM11-DC11 -> 0.1101 | DU11: 1 | DV11: 9883 | DW11: 16.9408 | DX11: 2.2701 | DY11: 0.8649 | DZ11: =DW11/24 -> 0.70586667 | EA11: =AJ11-DY11 -> 36.5951 | EE11: 1 | EF11: 9883 | EG11: 17.048 | EH11: 2.2845 | EI11: 0.8704 | EJ11: =EG11/24 -> 0.71033333 | EK11: =AJ11-EI11 -> 36.5896 | EM11: =EK11-EA11 -> -0.0055 | EO11: 1 | EP11: 9883 | EQ11: 17.2611 | ER11: 2.3131 | ES11: 0.8813 | ET11: =EQ11/24 -> 0.7192125 | EU11: =AJ11-ES11 -> 36.5787 | EY11: 1 | EZ11: 9883 | FA11: 17.3616 | FB11: 2.3265 | FC11: 0.8864 | FD11: =FA11/24 -> 0.7234 | FE11: =AJ11-FC11 -> 36.5736 | FG11: =FE11-EU11 -> -0.0051 | FI11: 1 | FJ11: 9883 | FK11: 17.4955 | FL11: 2.3445 | FM11: 0.8932 | FN11: =FK11/24 -> 0.72897917 | FO11: =AJ11-FM11 -> 36.5668 | FP11: =FO11-FE11 -> -0.0068 | FS11: 1 | FT11: 9883 | FU11: 17.5231 | FV11: 2.3482 | FW11: 0.8947 | FX11: =FU11/24 -> 0.73012917 | FY11: =AJ11-FW11 -> 36.5653 | FZ11: =FU11-FK11 -> 0.0276 | GC11: 1 | GD11: 9883 | GE11: 17.5913 | GF11: 2.3573 | GG11: 0.8981 | GH11: =GE11/24 -> 0.73297083 | GI11: =$AJ11-GG11 -> 36.5619 | GJ11: =GE11-FU11 -> 0.0682 | GM11: 1 | GN11: 9883 | GO11: 17.7357 | GP11: 2.3767 | GQ11: 0.9055 | GR11: =GO11/24 -> 0.7389875 | GS11: =$AJ11-GQ11 -> 36.5545 | GT11: =GO11-GE11 -> 0.1444 | GW11: 1 | GX11: 9883 | GY11: =VLOOKUP(GX11,Sheet3!$AJ$7:$AN$83,2,0) -> 17.9189 | GZ11: =VLOOKUP(GX11,Sheet3!$AJ$7:$AN$83,3,0) -> 2.4012 | HA11: =VLOOKUP(GX11,Sheet3!$AJ$7:$AN$83,4,0) -> 0.9149 | HB11: =GY11/24 -> 0.74662083 | HC11: =$AJ11-HA11 -> 36.5451 | HD11: =GY11-GO11 -> 0.1832 | HE11: =HA11-GQ11 -> 0.0094 | HH11: 1 | HI11: 9883 | HJ11: 17.9928 | HK11: 2.4111 | HL11: 0.9186 | HM11: =HJ11/24 -> 0.7497 | HN11: =$AJ11-HL11 -> 36.5414 | HO11: =HJ11-GY11 -> 0.0739 | HR11: 1 | HS11: 9883 | HT11: 18.041 | HU11: 2.4176 | HV11: 0.9211 | HW11: =HT11/24 -> 0.75170833 | HX11: =$AJ11-HV11 -> 36.5389 | HY11: =HT11-HJ11 -> 0.0482 | IB11: 1 | IC11: 9883 | ID11: 18.0619 | IE11: 2.4204 | IF11: 0.9222 | IG11: =ID11/24 -> 0.75257917 | IH11: =$AJ11-IF11 -> 36.5378 | II11: =ID11-HT11 -> 0.0209 | IL11: 1 | IM11: 9883 | IN11: 18.1717 | IO11: 2.4351 | IP11: 0.9278 | IQ11: =IN11/24 -> 0.75715417 | IR11: =$AJ11-IP11 -> 36.5322 | IS11: =IN11-ID11 -> 0.1098 | IV11: 1 | IW11: 9883 | IX11: 18.32 | IY11: 2.455 | IZ11: 0.9353 | JA11: =IX11/24 -> 0.76333333 | JB11: =$AJ11-IZ11 -> 36.5247 | JC11: =IX11-IN11 -> 0.1483 | JF11: 1 | JG11: 9883 | JH11: 18.3671 | JI11: 2.4613 | JJ11: 0.9377 | JK11: =JH11/24 -> 0.76529583 | JL11: =$AJ11-JJ11 -> 36.5223 | JM11: =JH11-IX11 -> 0.0471 | JP11: 1 | JQ11: 9883 | JR11: 18.405 | JS11: 2.4663 | JT11: 0.9397 | JU11: =JR11/24 -> 0.766875 | JV11: =$AJ11-JT11 -> 36.5203 | JW11: =JR11-JH11 -> 0.0379 | JZ11: 1 | KA11: 9883 | KB11: 18.4938 | KC11: 2.4782 | KD11: 0.9442 | KE11: =KB11/24 -> 0.770575 | KF11: =$AJ11-KD11 -> 36.5158 | KG11: =KB11-JR11 -> 0.0888 | KJ11: 1 | KK11: 9883 | KL11: 18.5235 | KM11: 2.4822 | KN11: 0.9457 | KO11: =KL11/24 -> 0.7718125 | KP11: =$AJ11-KN11 -> 36.5143 | KQ11: =KL11-KB11 -> 0.0297 | KT11: 1 | KU11: 9883 | KV11: 18.5547 | KW11: 2.4864 | KX11: 0.9473 | KY11: =KV11/24 -> 0.7731125 | KZ11: =$AJ11-KX11 -> 36.5127 | LA11: =KV11-KL11 -> 0.0312 | LD11: 1 | LE11: 9883 | LF11: 18.5808 | LG11: 2.4899 | LH11: 0.9487 | LI11: =LF11/24 -> 0.7742 | LJ11: =$AJ11-LH11 -> 36.5113 | LK11: =LF11-KV11 -> 0.0261 | LN11: 1 | LO11: 9883 | LP11: 18.6174 | LQ11: 2.4948 | LR11: 0.9505 | LS11: =LP11/24 -> 0.775725 | LT11: =$AJ11-LR11 -> 36.5095 | LU11: =LP11-LF11 -> 0.0366 | LX11: 1 | LY11: 9883 | LZ11: 18.6586 | MA11: 2.5003 | MB11: 0.9526 | MC11: =LZ11/24 -> 0.77744167 | MD11: =$AJ11-MB11 -> 36.5074 | ME11: =LZ11-LP11 -> 0.0412 | MH11: 1 | MI11: 9883 | MJ11: 18.6991 | MK11: 2.5058 | ML11: 0.9547 | MM11: =MJ11/24 -> 0.77912917 | MN11: =$AJ11-ML11 -> 36.5053 | MO11: =MJ11-LZ11 -> 0.0405 | MR11: 1 | MS11: 9883 | MT11: 18.7764 | MU11: 2.5161 | MV11: 0.9586 | MW11: =MT11/24 -> 0.78235 | MX11: =$AJ11-MV11 -> 36.5014 | MY11: =MT11-MJ11 -> 0.0773 | NB11: 1 | NC11: 9883 | ND11: 18.8554 | NE11: 2.5267 | NF11: 0.9627 | NG11: =ND11/24 -> 0.78564167 | NH11: =$AJ11-NF11 -> 36.4973 | NI11: =ND11-MT11 -> 0.079 | NL11: 1 | NM11: 9883 | NN11: 18.8787 | NO11: 2.5298 | NP11: 0.9639 | NQ11: =NN11/24 -> 0.7866125 | NR11: =$AJ11-NP11 -> 36.4961 | NS11: =NN11-ND11 -> 0.0233 | NV11: 1 | NW11: 9883 | NX11: 18.9156 | NY11: 2.5348 | NZ11: 0.9657 | OA11: =NX11/24 -> 0.78815 | OB11: =$AJ11-NZ11 -> 36.4943 | OC11: =NX11-NN11 -> 0.0369 | OF11: 1 | OG11: 9883 | OH11: 18.9341 | OI11: 2.5372 | OJ11: 0.9667 | OK11: =OH11/24 -> 0.78892083 | OL11: =$AJ11-OJ11 -> 36.4933 | OM11: =OH11-NX11 -> 0.0185 | OP11: 1 | OQ11: 9883 | OR11: =VLOOKUP(OQ11,Sheet4!A9:F85,3,0) -> 18.9765 | OS11: =VLOOKUP(OQ11,Sheet4!A9:F85,4,0) -> 2.5429 | OT11: =VLOOKUP(OQ11,Sheet4!A9:F85,5,0) -> 0.9689 | OU11: =OR11/24 -> 0.7906875 | OV11: =$AJ11-OT11 -> 36.4911 | OW11: =OR11-OH11 -> 0.0424
A12: 4 | B12: 9987 | C12: B | D12: 38.51 | J12: 9987 | K12: 10.7465 | L12: 1.4401 | M12: 0.5487 | N12: =K12/24 -> 0.44777083 | O12: =D12-M12 -> 37.9613 | R12: 9987 | S12: 10.8416 | T12: 1.4528 | U12: 0.5535 | V12: =S12/24 -> 0.45173333 | W12: =D12-U12 -> 37.9565 | Z12: 9987 | AA12: 11.0752 | AB12: 1.4841 | AC12: 0.5654 | AD12: =AA12/24 -> 0.46146667 | AE12: =D12-AC12 -> 37.9446 | AG12: 4 | AH12: 9987 | AI12: B | AJ12: 38.51 | AL12: 9987 | AM12: 11.3276 | AN12: 1.5179 | AO12: 0.5783 | AP12: =AM12/24 -> 0.47198333 | AQ12: =AJ12-AO12 -> 37.9317 | AU12: 9987 | AV12: 11.4349 | AW12: 1.5323 | AX12: 0.5838 | AY12: =AV12/24 -> 0.47645417 | AZ12: =AJ12-AX12 -> 37.9262 | BA12: =MAX(AZ11:AZ81) -> 37.9918 | BD12: 9987 | BE12: 11.4471 | BF12: 1.534 | BG12: 0.5844 | BH12: =BE12/24 -> 0.4769625 | BI12: =AJ12-BG12 -> 37.9256 | BN12: 9987 | BO12: 11.4924 | BP12: 1.54 | BQ12: 0.5868 | BR12: =BO12/24 -> 0.47885 | BS12: =AJ12-BQ12 -> 37.9232 | BX12: 9987 | BY12: 11.5816 | BZ12: 1.552 | CA12: 0.5913 | CB12: =BY12/24 -> 0.48256667 | CC12: =AJ12-CA12 -> 37.9187 | CG12: 2 | CH12: 9987 | CI12: 11.6583 | CJ12: 1.5623 | CK12: 0.5952 | CL12: =CI12/24 -> 0.4857625 | CM12: =AJ12-CK12 -> 37.9148 | CQ12: 2 | CR12: 9987 | CS12: 11.7548 | CT12: 1.5752 | CU12: 0.6001 | CV12: =CS12/24 -> 0.48978333 | CW12: =AJ12-CU12 -> 37.9099 | DA12: 2 | DB12: 9987 | DC12: 11.7643 | DD12: 1.5765 | DE12: 0.6006 | DF12: =DC12/24 -> 0.49017917 | DG12: =AJ12-DE12 -> 37.9094 | DK12: 2 | DL12: 9987 | DM12: 11.8744 | DN12: 1.5912 | DO12: 0.6063 | DP12: =DM12/24 -> 0.49476667 | DQ12: =AJ12-DO12 -> 37.9037 | DS12: =DM12-DC12 -> 0.1101 | DU12: 2 | DV12: 9987 | DW12: 11.943 | DX12: 1.6004 | DY12: 0.6098 | DZ12: =DW12/24 -> 0.497625 | EA12: =AJ12-DY12 -> 37.9002 | EE12: 2 | EF12: 9987 | EG12: 12.0502 | EH12: 1.6148 | EI12: 0.6152 | EJ12: =EG12/24 -> 0.50209167 | EK12: =AJ12-EI12 -> 37.8948 | EM12: =EK12-EA12 -> -0.0054 | EO12: 2 | EP12: 9987 | EQ12: 12.2633 | ER12: 1.6433 | ES12: 0.6261 | ET12: =EQ12/24 -> 0.51097083 | EU12: =AJ12-ES12 -> 37.8839 | EY12: 2 | EZ12: 9987 | FA12: 12.3638 | FB12: 1.6568 | FC12: 0.6312 | FD12: =FA12/24 -> 0.51515833 | FE12: =AJ12-FC12 -> 37.8788 | FG12: =FE12-EU12 -> -0.0051 | FI12: 2 | FJ12: 9987 | FK12: 12.4977 | FL12: 1.6747 | FM12: 0.6381 | FN12: =FK12/24 -> 0.5207375 | FO12: =AJ12-FM12 -> 37.8719 | FP12: =FO12-FE12 -> -0.0069 | FS12: 2 | FT12: 9987 | FU12: 12.5253 | FV12: 1.6784 | FW12: 0.6395 | FX12: 0.5544 | FY12: =AJ12-FW12 -> 37.8705 | FZ12: =FU12-FK12 -> 0.0276 | GC12: 2 | GD12: 9987 | GE12: 12.5935 | GF12: 1.6876 | GG12: 0.643 | GH12: 0.5544 | GI12: =$AJ12-GG12 -> 37.867 | GJ12: =GE12-FU12 -> 0.0682 | GM12: 2 | GN12: 9987 | GO12: 12.7379 | GP12: 1.7069 | GQ12: 0.6503 | GR12: =GO12/24 -> 0.53074583 | GS12: =$AJ12-GQ12 -> 37.8597 | GT12: =GO12-GE12 -> 0.1444 | GW12: 2 | GX12: 9987 | GY12: =VLOOKUP(GX12,Sheet3!$AJ$7:$AN$83,2,0) -> 12.9211 | GZ12: =VLOOKUP(GX12,Sheet3!$AJ$7:$AN$83,3,0) -> 1.7315 | HA12: =VLOOKUP(GX12,Sheet3!$AJ$7:$AN$83,4,0) -> 0.6597 | HB12: =GY12/24 -> 0.53837917 | HC12: =$AJ12-HA12 -> 37.8503 | HD12: =GY12-GO12 -> 0.1832 | HE12: =HA12-GQ12 -> 0.0094 | HH12: 2 | HI12: 9987 | HJ12: 12.995 | HK12: 1.7414 | HL12: 0.6635 | HM12: =HJ12/24 -> 0.54145833 | HN12: =$AJ12-HL12 -> 37.8465 | HO12: =HJ12-GY12 -> 0.0739 | HR12: 2 | HS12: 9987 | HT12: 13.0432 | HU12: 1.7478 | HV12: 0.6659 | HW12: =HT12/24 -> 0.54346667 | HX12: =$AJ12-HV12 -> 37.8441 | HY12: =HT12-HJ12 -> 0.0482 | IB12: 2 | IC12: 9987 | ID12: 13.0641 | IE12: 1.7506 | IF12: 0.667 | IG12: =ID12/24 -> 0.5443375 | IH12: =$AJ12-IF12 -> 37.843 | II12: =ID12-HT12 -> 0.0209 | IL12: 2 | IM12: 9987 | IN12: 13.1739 | IO12: 1.7654 | IP12: 0.6726 | IQ12: =IN12/24 -> 0.5489125 | IR12: =$AJ12-IP12 -> 37.8374 | IS12: =IN12-ID12 -> 0.1098 | IV12: 2 | IW12: 9987 | IX12: 13.3222 | IY12: 1.7852 | IZ12: 0.6802 | JA12: =IX12/24 -> 0.55509167 | JB12: =$AJ12-IZ12 -> 37.8298 | JC12: =IX12-IN12 -> 0.1483 | JF12: 2 | JG12: 9987 | JH12: 13.3693 | JI12: 1.7915 | JJ12: 0.6826 | JK12: =JH12/24 -> 0.55705417 | JL12: =$AJ12-JJ12 -> 37.8274 | JM12: =JH12-IX12 -> 0.0471 | JP12: 2 | JQ12: 9987 | JR12: 13.4072 | JS12: 1.7966 | JT12: 0.6845 | JU12: =JR12/24 -> 0.55863333 | JV12: =$AJ12-JT12 -> 37.8255 | JW12: =JR12-JH12 -> 0.0379 | JZ12: 2 | KA12: 9987 | KB12: 13.496 | KC12: 1.8085 | KD12: 0.689 | KE12: =KB12/24 -> 0.56233333 | KF12: =$AJ12-KD12 -> 37.821 | KG12: =KB12-JR12 -> 0.0888 | KJ12: 2 | KK12: 9987 | KL12: 13.5257 | KM12: 1.8125 | KN12: 0.6906 | KO12: =KL12/24 -> 0.56357083 | KP12: =$AJ12-KN12 -> 37.8194 | KQ12: =KL12-KB12 -> 0.0297 | KT12: 2 | KU12: 9987 | KV12: 13.5569 | KW12: 1.8167 | KX12: 0.6922 | KY12: =KV12/24 -> 0.56487083 | KZ12: =$AJ12-KX12 -> 37.8178 | LA12: =KV12-KL12 -> 0.0312 | LD12: 2 | LE12: 9987 | LF12: 13.583 | LG12: 1.8202 | LH12: 0.6935 | LI12: =LF12/24 -> 0.56595833 | LJ12: =$AJ12-LH12 -> 37.8165 | LK12: =LF12-KV12 -> 0.0261 | LN12: 2 | LO12: 9987 | LP12: 13.6196 | LQ12: 1.8251 | LR12: 0.6954 | LS12: =LP12/24 -> 0.56748333 | LT12: =$AJ12-LR12 -> 37.8146 | LU12: =LP12-LF12 -> 0.0366 | LX12: 2 | LY12: 9987 | LZ12: 13.6608 | MA12: 1.8306 | MB12: 0.6975 | MC12: =LZ12/24 -> 0.5692 | MD12: =$AJ12-MB12 -> 37.8125 | ME12: =LZ12-LP12 -> 0.0412 | MH12: 2 | MI12: 9987 | MJ12: 13.7013 | MK12: 1.836 | ML12: 0.6995 | MM12: =MJ12/24 -> 0.5708875 | MN12: =$AJ12-ML12 -> 37.8105 | MO12: =MJ12-LZ12 -> 0.0405 | MR12: 2 | MS12: 9987 | MT12: 13.7786 | MU12: 1.8464 | MV12: 0.7035 | MW12: =MT12/24 -> 0.57410833 | MX12: =$AJ12-MV12 -> 37.8065 | MY12: =MT12-MJ12 -> 0.0773 | NB12: 2 | NC12: 9987 | ND12: 13.8576 | NE12: 1.857 | NF12: 0.7075 | NG12: =ND12/24 -> 0.5774 | NH12: =$AJ12-NF12 -> 37.8025 | NI12: =ND12-MT12 -> 0.079 | NL12: 2 | NM12: 9987 | NN12: 13.8809 | NO12: 1.8601 | NP12: 0.7087 | NQ12: =NN12/24 -> 0.57837083 | NR12: =$AJ12-NP12 -> 37.8013 | NS12: =NN12-ND12 -> 0.0233 | NV12: 2 | NW12: 9987 | NX12: 13.9178 | NY12: 1.865 | NZ12: 0.7106 | OA12: =NX12/24 -> 0.57990833 | OB12: =$AJ12-NZ12 -> 37.7994 | OC12: =NX12-NN12 -> 0.0369 | OF12: 2 | OG12: 9987 | OH12: 13.9363 | OI12: 1.8675 | OJ12: 0.7115 | OK12: =OH12/24 -> 0.58067917 | OL12: =$AJ12-OJ12 -> 37.7985 | OM12: =OH12-NX12 -> 0.0185 | OP12: 2 | OQ12: 9987 | OR12: =VLOOKUP(OQ12,Sheet4!A10:F86,3,0) -> 13.9787 | OS12: =VLOOKUP(OQ12,Sheet4!A10:F86,4,0) -> 1.8732 | OT12: =VLOOKUP(OQ12,Sheet4!A10:F86,5,0) -> 0.7137 | OU12: =OR12/24 -> 0.58244583 | OV12: =$AJ12-OT12 -> 37.7963 | OW12: =OR12-OH12 -> 0.0424
A13: 5 | B13: 9996 | C13: B | D13: 38.44 | J13: 9996 | K13: 11.0345 | L13: 1.4787 | M13: 0.5634 | N13: =K13/24 -> 0.45977083 | O13: =D13-M13 -> 37.8766 | R13: 9996 | S13: 11.1296 | T13: 1.4914 | U13: 0.5682 | V13: =S13/24 -> 0.46373333 | W13: =D13-U13 -> 37.8718 | Z13: 9996 | AA13: 11.3632 | AB13: 1.5227 | AC13: 0.5802 | AD13: =AA13/24 -> 0.47346667 | AE13: =D13-AC13 -> 37.8598 | AG13: 5 | AH13: 9996 | AI13: B | AJ13: 38.44 | AL13: 9996 | AM13: 11.6156 | AN13: 1.5565 | AO13: 0.593 | AP13: =AM13/24 -> 0.48398333 | AQ13: =AJ13-AO13 -> 37.847 | AU13: 9996 | AV13: 11.7229 | AW13: 1.5709 | AX13: 0.5985 | AY13: =AV13/24 -> 0.48845417 | AZ13: =AJ13-AX13 -> 37.8415 | BA13: =MIN(AZ11:AZ81) -> 34.985 | BD13: 9996 | BE13: 11.7351 | BF13: 1.5725 | BG13: 0.5991 | BH13: =BE13/24 -> 0.4889625 | BI13: =AJ13-BG13 -> 37.8409 | BN13: 9996 | BO13: 11.7804 | BP13: 1.5786 | BQ13: 0.6015 | BR13: =BO13/24 -> 0.49085 | BS13: =AJ13-BQ13 -> 37.8385 | BX13: 9996 | BY13: 11.8696 | BZ13: 1.5906 | CA13: 0.606 | CB13: =BY13/24 -> 0.49456667 | CC13: =AJ13-CA13 -> 37.834 | CG13: 3 | CH13: 9996 | CI13: 11.9463 | CJ13: 1.6009 | CK13: 0.6099 | CL13: =CI13/24 -> 0.4977625 | CM13: =AJ13-CK13 -> 37.8301 | CQ13: 3 | CR13: 9996 | CS13: 12.0428 | CT13: 1.6138 | CU13: 0.6149 | CV13: =CS13/24 -> 0.50178333 | CW13: =AJ13-CU13 -> 37.8251 | DA13: 3 | DB13: 9996 | DC13: 12.0523 | DD13: 1.6151 | DE13: 0.6153 | DF13: =DC13/24 -> 0.50217917 | DG13: =AJ13-DE13 -> 37.8247 | DK13: 3 | DL13: 9996 | DM13: 12.1624 | DN13: 1.6298 | DO13: 0.621 | DP13: =DM13/24 -> 0.50676667 | DQ13: =AJ13-DO13 -> 37.819 | DS13: =DM13-DC13 -> 0.1101 | DU13: 3 | DV13: 9996 | DW13: 12.231 | DX13: 1.639 | DY13: 0.6245 | DZ13: =DW13/24 -> 0.509625 | EA13: =AJ13-DY13 -> 37.8155 | EE13: 3 | EF13: 9996 | EG13: 12.3382 | EH13: 1.6534 | EI13: 0.6299 | EJ13: =EG13/24 -> 0.51409167 | EK13: =AJ13-EI13 -> 37.8101 | EM13: =EK13-EA13 -> -0.0054 | EO13: 3 | EP13: 9996 | EQ13: 12.5513 | ER13: 1.6819 | ES13: 0.6408 | ET13: =EQ13/24 -> 0.52297083 | EU13: =AJ13-ES13 -> 37.7992 | EY13: 3 | EZ13: 9996 | FA13: 12.6518 | FB13: 1.6954 | FC13: 0.6459 | FD13: =FA13/24 -> 0.52715833 | FE13: =AJ13-FC13 -> 37.7941 | FG13: =FE13-EU13 -> -0.0051 | FI13: 3 | FJ13: 9996 | FK13: 12.7857 | FL13: 1.7133 | FM13: 0.6528 | FN13: =FK13/24 -> 0.5327375 | FO13: =AJ13-FM13 -> 37.7872 | FP13: =FO13-FE13 -> -0.0069 | FS13: 3 | FT13: 9996 | FU13: 12.8133 | FV13: 1.717 | FW13: 0.6542 | FX13: =FU13/24 -> 0.5338875 | FY13: =AJ13-FW13 -> 37.7858 | FZ13: =FU13-FK13 -> 0.0276 | GC13: 3 | GD13: 9996 | GE13: 12.8815 | GF13: 1.7262 | GG13: 0.6577 | GH13: =GE13/24 -> 0.53672917 | GI13: =$AJ13-GG13 -> 37.7823 | GJ13: =GE13-FU13 -> 0.0682 | GM13: 3 | GN13: 9996 | GO13: 13.0259 | GP13: 1.7455 | GQ13: 0.665 | GR13: =GO13/24 -> 0.54274583 | GS13: =$AJ13-GQ13 -> 37.775 | GT13: =GO13-GE13 -> 0.1444 | GW13: 3 | GX13: 9996 | GY13: =VLOOKUP(GX13,Sheet3!$AJ$7:$AN$83,2,0) -> 13.2091 | GZ13: =VLOOKUP(GX13,Sheet3!$AJ$7:$AN$83,3,0) -> 1.7701 | HA13: =VLOOKUP(GX13,Sheet3!$AJ$7:$AN$83,4,0) -> 0.6744 | HB13: =GY13/24 -> 0.55037917 | HC13: =$AJ13-HA13 -> 37.7656 | HD13: =GY13-GO13 -> 0.1832 | HE13: =HA13-GQ13 -> 0.0094 | HH13: 3 | HI13: 9996 | HJ13: 13.283 | HK13: 1.78 | HL13: 0.6782 | HM13: =HJ13/24 -> 0.55345833 | HN13: =$AJ13-HL13 -> 37.7618 | HO13: =HJ13-GY13 -> 0.0739 | HR13: 3 | HS13: 9996 | HT13: 13.3312 | HU13: 1.7864 | HV13: 0.6806 | HW13: =HT13/24 -> 0.55546667 | HX13: =$AJ13-HV13 -> 37.7594 | HY13: =HT13-HJ13 -> 0.0482 | IB13: 3 | IC13: 9996 | ID13: 13.3521 | IE13: 1.7892 | IF13: 0.6817 | IG13: =ID13/24 -> 0.5563375 | IH13: =$AJ13-IF13 -> 37.7583 | II13: =ID13-HT13 -> 0.0209 | IL13: 3 | IM13: 9996 | IN13: 13.4619 | IO13: 1.8039 | IP13: 0.6873 | IQ13: =IN13/24 -> 0.5609125 | IR13: =$AJ13-IP13 -> 37.7527 | IS13: =IN13-ID13 -> 0.1098 | IV13: 3 | IW13: 9996 | IX13: 13.6102 | IY13: 1.8238 | IZ13: 0.6949 | JA13: =IX13/24 -> 0.56709167 | JB13: =$AJ13-IZ13 -> 37.7451 | JC13: =IX13-IN13 -> 0.1483 | JF13: 3 | JG13: 9996 | JH13: 13.6573 | JI13: 1.8301 | JJ13: 0.6973 | JK13: =JH13/24 -> 0.56905417 | JL13: =$AJ13-JJ13 -> 37.7427 | JM13: =JH13-IX13 -> 0.0471 | JP13: 3 | JQ13: 9996 | JR13: 13.6952 | JS13: 1.8352 | JT13: 0.6992 | JU13: =JR13/24 -> 0.57063333 | JV13: =$AJ13-JT13 -> 37.7408 | JW13: =JR13-JH13 -> 0.0379 | JZ13: 3 | KA13: 9996 | KB13: 13.784 | KC13: 1.8471 | KD13: 0.7037 | KE13: =KB13/24 -> 0.57433333 | KF13: =$AJ13-KD13 -> 37.7363 | KG13: =KB13-JR13 -> 0.0888 | KJ13: 3 | KK13: 9996 | KL13: 13.8137 | KM13: 1.8511 | KN13: 0.7053 | KO13: =KL13/24 -> 0.57557083 | KP13: =$AJ13-KN13 -> 37.7347 | KQ13: =KL13-KB13 -> 0.0297 | KT13: 3 | KU13: 9996 | KV13: 13.8449 | KW13: 1.8553 | KX13: 0.7069 | KY13: =KV13/24 -> 0.57687083 | KZ13: =$AJ13-KX13 -> 37.7331 | LA13: =KV13-KL13 -> 0.0312 | LD13: 3 | LE13: 9996 | LF13: 13.871 | LG13: 1.8588 | LH13: 0.7082 | LI13: =LF13/24 -> 0.57795833 | LJ13: =$AJ13-LH13 -> 37.7318 | LK13: =LF13-KV13 -> 0.0261 | LN13: 3 | LO13: 9996 | LP13: 13.9076 | LQ13: 1.8637 | LR13: 0.7101 | LS13: =LP13/24 -> 0.57948333 | LT13: =$AJ13-LR13 -> 37.7299 | LU13: =LP13-LF13 -> 0.0366 | LX13: 3 | LY13: 9996 | LZ13: 13.9488 | MA13: 1.8692 | MB13: 0.7122 | MC13: =LZ13/24 -> 0.5812 | MD13: =$AJ13-MB13 -> 37.7278 | ME13: =LZ13-LP13 -> 0.0412 | MH13: 3 | MI13: 9996 | MJ13: 13.9893 | MK13: 1.8746 | ML13: 0.7142 | MM13: =MJ13/24 -> 0.5828875 | MN13: =$AJ13-ML13 -> 37.7258 | MO13: =MJ13-LZ13 -> 0.0405 | MR13: 3 | MS13: 9996 | MT13: 14.0666 | MU13: 1.885 | MV13: 0.7182 | MW13: =MT13/24 -> 0.58610833 | MX13: =$AJ13-MV13 -> 37.7218 | MY13: =MT13-MJ13 -> 0.0773 | NB13: 3 | NC13: 9996 | ND13: 14.1456 | NE13: 1.8956 | NF13: 0.7222 | NG13: =ND13/24 -> 0.5894 | NH13: =$AJ13-NF13 -> 37.7178 | NI13: =ND13-MT13 -> 0.079 | NL13: 3 | NM13: 9996 | NN13: 14.1689 | NO13: 1.8987 | NP13: 0.7234 | NQ13: =NN13/24 -> 0.59037083 | NR13: =$AJ13-NP13 -> 37.7166 | NS13: =NN13-ND13 -> 0.0233 | NV13: 3 | NW13: 9996 | NX13: 14.2058 | NY13: 1.9036 | NZ13: 0.7253 | OA13: =NX13/24 -> 0.59190833 | OB13: =$AJ13-NZ13 -> 37.7147 | OC13: =NX13-NN13 -> 0.0369 | OF13: 3 | OG13: 9996 | OH13: 14.2243 | OI13: 1.9061 | OJ13: 0.7262 | OK13: =OH13/24 -> 0.59267917 | OL13: =$AJ13-OJ13 -> 37.7138 | OM13: =OH13-NX13 -> 0.0185 | OP13: 3 | OQ13: 9996 | OR13: =VLOOKUP(OQ13,Sheet4!A11:F87,3,0) -> 14.2667 | OS13: =VLOOKUP(OQ13,Sheet4!A11:F87,4,0) -> 1.9118 | OT13: =VLOOKUP(OQ13,Sheet4!A11:F87,5,0) -> 0.7284 | OU13: =OR13/24 -> 0.59444583 | OV13: =$AJ13-OT13 -> 37.7116 | OW13: =OR13-OH13 -> 0.0424
A14: 6 | B14: 9988 | C14: B | D14: 38.4 | J14: 9988 | K14: 11.0345 | L14: 1.4787 | M14: 0.5634 | N14: =K14/24 -> 0.45977083 | O14: =D14-M14 -> 37.8366 | R14: 9988 | S14: 11.1296 | T14: 1.4914 | U14: 0.5682 | V14: =S14/24 -> 0.46373333 | W14: =D14-U14 -> 37.8318 | Z14: 9988 | AA14: 11.3632 | AB14: 1.5227 | AC14: 0.5802 | AD14: =AA14/24 -> 0.47346667 | AE14: =D14-AC14 -> 37.8198 | AG14: 6 | AH14: 9988 | AI14: B | AJ14: 38.4 | AL14: 9988 | AM14: 11.6156 | AN14: 1.5565 | AO14: 0.593 | AP14: =AM14/24 -> 0.48398333 | AQ14: =AJ14-AO14 -> 37.807 | AU14: 9988 | AV14: 11.7229 | AW14: 1.5709 | AX14: 0.5985 | AY14: =AV14/24 -> 0.48845417 | AZ14: =AJ14-AX14 -> 37.8015 | BD14: 9988 | BE14: 11.7351 | BF14: 1.5725 | BG14: 0.5991 | BH14: =BE14/24 -> 0.4889625 | BI14: =AJ14-BG14 -> 37.8009 | BN14: 9988 | BO14: 11.7804 | BP14: 1.5786 | BQ14: 0.6015 | BR14: =BO14/24 -> 0.49085 | BS14: =AJ14-BQ14 -> 37.7985 | BX14: 9988 | BY14: 11.8696 | BZ14: 1.5906 | CA14: 0.606 | CB14: =BY14/24 -> 0.49456667 | CC14: =AJ14-CA14 -> 37.794 | CG14: 4 | CH14: 9988 | CI14: 11.9463 | CJ14: 1.6009 | CK14: 0.6099 | CL14: =CI14/24 -> 0.4977625 | CM14: =AJ14-CK14 -> 37.7901 | CQ14: 4 | CR14: 9988 | CS14: 12.0428 | CT14: 1.6138 | CU14: 0.6149 | CV14: =CS14/24 -> 0.50178333 | CW14: =AJ14-CU14 -> 37.7851 | DA14: 4 | DB14: 9988 | DC14: 12.0523 | DD14: 1.6151 | DE14: 0.6153 | DF14: =DC14/24 -> 0.50217917 | DG14: =AJ14-DE14 -> 37.7847 | DK14: 4 | DL14: 9988 | DM14: 12.1624 | DN14: 1.6298 | DO14: 0.621 | DP14: =DM14/24 -> 0.50676667 | DQ14: =AJ14-DO14 -> 37.779 | DS14: =DM14-DC14 -> 0.1101 | DU14: 4 | DV14: 9988 | DW14: 12.231 | DX14: 1.639 | DY14: 0.6245 | DZ14: =DW14/24 -> 0.509625 | EA14: =AJ14-DY14 -> 37.7755 | EE14: 4 | EF14: 9988 | EG14: 12.3382 | EH14: 1.6534 | EI14: 0.6299 | EJ14: =EG14/24 -> 0.51409167 | EK14: =AJ14-EI14 -> 37.7701 | EM14: =EK14-EA14 -> -0.0054 | EO14: 4 | EP14: 9988 | EQ14: 12.5513 | ER14: 1.6819 | ES14: 0.6408 | ET14: =EQ14/24 -> 0.52297083 | EU14: =AJ14-ES14 -> 37.7592 | EY14: 4 | EZ14: 9988 | FA14: 12.6518 | FB14: 1.6954 | FC14: 0.6459 | FD14: =FA14/24 -> 0.52715833 | FE14: =AJ14-FC14 -> 37.7541 | FG14: =FE14-EU14 -> -0.0051 | FI14: 4 | FJ14: 9988 | FK14: 12.7857 | FL14: 1.7133 | FM14: 0.6528 | FN14: =FK14/24 -> 0.5327375 | FO14: =AJ14-FM14 -> 37.7472 | FP14: =FO14-FE14 -> -0.0069 | FS14: 4 | FT14: 9988 | FU14: 12.8133 | FV14: 1.717 | FW14: 0.6542 | FX14: =FU14/24 -> 0.5338875 | FY14: =AJ14-FW14 -> 37.7458 | FZ14: =FU14-FK14 -> 0.0276 | GC14: 4 | GD14: 9988 | GE14: 12.8815 | GF14: 1.7262 | GG14: 0.6577 | GH14: =GE14/24 -> 0.53672917 | GI14: =$AJ14-GG14 -> 37.7423 | GJ14: =GE14-FU14 -> 0.0682 | GM14: 4 | GN14: 9988 | GO14: 13.0259 | GP14: 1.7455 | GQ14: 0.665 | GR14: =GO14/24 -> 0.54274583 | GS14: =$AJ14-GQ14 -> 37.735 | GT14: =GO14-GE14 -> 0.1444 | GW14: 4 | GX14: 9988 | GY14: =VLOOKUP(GX14,Sheet3!$AJ$7:$AN$83,2,0) -> 13.2091 | GZ14: =VLOOKUP(GX14,Sheet3!$AJ$7:$AN$83,3,0) -> 1.7701 | HA14: =VLOOKUP(GX14,Sheet3!$AJ$7:$AN$83,4,0) -> 0.6744 | HB14: =GY14/24 -> 0.55037917 | HC14: =$AJ14-HA14 -> 37.7256 | HD14: =GY14-GO14 -> 0.1832 | HE14: =HA14-GQ14 -> 0.0094 | HH14: 4 | HI14: 9988 | HJ14: 13.283 | HK14: 1.78 | HL14: 0.6782 | HM14: =HJ14/24 -> 0.55345833 | HN14: =$AJ14-HL14 -> 37.7218 | HO14: =HJ14-GY14 -> 0.0739 | HR14: 4 | HS14: 9988 | HT14: 13.3312 | HU14: 1.7864 | HV14: 0.6806 | HW14: =HT14/24 -> 0.55546667 | HX14: =$AJ14-HV14 -> 37.7194 | HY14: =HT14-HJ14 -> 0.0482 | IB14: 4 | IC14: 9988 | ID14: 13.3521 | IE14: 1.7892 | IF14: 0.6817 | IG14: =ID14/24 -> 0.5563375 | IH14: =$AJ14-IF14 -> 37.7183 | II14: =ID14-HT14 -> 0.0209 | IL14: 4 | IM14: 9988 | IN14: 13.4619 | IO14: 1.8039 | IP14: 0.6873 | IQ14: =IN14/24 -> 0.5609125 | IR14: =$AJ14-IP14 -> 37.7127 | IS14: =IN14-ID14 -> 0.1098 | IV14: 4 | IW14: 9988 | IX14: 13.6102 | IY14: 1.8238 | IZ14: 0.6949 | JA14: =IX14/24 -> 0.56709167 | JB14: =$AJ14-IZ14 -> 37.7051 | JC14: =IX14-IN14 -> 0.1483 | JF14: 4 | JG14: 9988 | JH14: 13.6573 | JI14: 1.8301 | JJ14: 0.6973 | JK14: =JH14/24 -> 0.56905417 | JL14: =$AJ14-JJ14 -> 37.7027 | JM14: =JH14-IX14 -> 0.0471 | JP14: 4 | JQ14: 9988 | JR14: 13.6952 | JS14: 1.8352 | JT14: 0.6992 | JU14: =JR14/24 -> 0.57063333 | JV14: =$AJ14-JT14 -> 37.7008 | JW14: =JR14-JH14 -> 0.0379 | JZ14: 4 | KA14: 9988 | KB14: 13.784 | KC14: 1.8471 | KD14: 0.7037 | KE14: =KB14/24 -> 0.57433333 | KF14: =$AJ14-KD14 -> 37.6963 | KG14: =KB14-JR14 -> 0.0888 | KJ14: 4 | KK14: 9988 | KL14: 13.8137 | KM14: 1.8511 | KN14: 0.7053 | KO14: =KL14/24 -> 0.57557083 | KP14: =$AJ14-KN14 -> 37.6947 | KQ14: =KL14-KB14 -> 0.0297 | KT14: 4 | KU14: 9988 | KV14: 13.8449 | KW14: 1.8553 | KX14: 0.7069 | KY14: =KV14/24 -> 0.57687083 | KZ14: =$AJ14-KX14 -> 37.6931 | LA14: =KV14-KL14 -> 0.0312 | LD14: 4 | LE14: 9988 | LF14: 13.871 | LG14: 1.8588 | LH14: 0.7082 | LI14: =LF14/24 -> 0.57795833 | LJ14: =$AJ14-LH14 -> 37.6918 | LK14: =LF14-KV14 -> 0.0261 | LN14: 4 | LO14: 9988 | LP14: 13.9076 | LQ14: 1.8637 | LR14: 0.7101 | LS14: =LP14/24 -> 0.57948333 | LT14: =$AJ14-LR14 -> 37.6899 | LU14: =LP14-LF14 -> 0.0366 | LX14: 4 | LY14: 9988 | LZ14: 13.9488 | MA14: 1.8692 | MB14: 0.7122 | MC14: =LZ14/24 -> 0.5812 | MD14: =$AJ14-MB14 -> 37.6878 | ME14: =LZ14-LP14 -> 0.0412 | MH14: 4 | MI14: 9988 | MJ14: 13.9893 | MK14: 1.8746 | ML14: 0.7142 | MM14: =MJ14/24 -> 0.5828875 | MN14: =$AJ14-ML14 -> 37.6858 | MO14: =MJ14-LZ14 -> 0.0405 | MR14: 4 | MS14: 9988 | MT14: 14.0666 | MU14: 1.885 | MV14: 0.7182 | MW14: =MT14/24 -> 0.58610833 | MX14: =$AJ14-MV14 -> 37.6818 | MY14: =MT14-MJ14 -> 0.0773 | NB14: 4 | NC14: 9988 | ND14: 14.1456 | NE14: 1.8956 | NF14: 0.7222 | NG14: =ND14/24 -> 0.5894 | NH14: =$AJ14-NF14 -> 37.6778 | NI14: =ND14-MT14 -> 0.079 | NL14: 4 | NM14: 9988 | NN14: 14.1689 | NO14: 1.8987 | NP14: 0.7234 | NQ14: =NN14/24 -> 0.59037083 | NR14: =$AJ14-NP14 -> 37.6766 | NS14: =NN14-ND14 -> 0.0233 | NV14: 4 | NW14: 9988 | NX14: 14.2058 | NY14: 1.9036 | NZ14: 0.7253 | OA14: =NX14/24 -> 0.59190833 | OB14: =$AJ14-NZ14 -> 37.6747 | OC14: =NX14-NN14 -> 0.0369 | OF14: 4 | OG14: 9988 | OH14: 14.2243 | OI14: 1.9061 | OJ14: 0.7262 | OK14: =OH14/24 -> 0.59267917 | OL14: =$AJ14-OJ14 -> 37.6738 | OM14: =OH14-NX14 -> 0.0185 | OP14: 4 | OQ14: 9988 | OR14: =VLOOKUP(OQ14,Sheet4!A12:F88,3,0) -> 14.2667 | OS14: =VLOOKUP(OQ14,Sheet4!A12:F88,4,0) -> 1.9118 | OT14: =VLOOKUP(OQ14,Sheet4!A12:F88,5,0) -> 0.7284 | OU14: =OR14/24 -> 0.59444583 | OV14: =$AJ14-OT14 -> 37.6716 | OW14: =OR14-OH14 -> 0.0424
A15: 7 | B15: 9994 | C15: B | D15: 38.5 | J15: 9994 | K15: 11.0345 | L15: 1.4787 | M15: 0.5634 | N15: =K15/24 -> 0.45977083 | O15: =D15-M15 -> 37.9366 | R15: 9994 | S15: 11.1296 | T15: 1.4914 | U15: 0.5682 | V15: =S15/24 -> 0.46373333 | W15: =D15-U15 -> 37.9318 | Z15: 9994 | AA15: 11.3632 | AB15: 1.5227 | AC15: 0.5802 | AD15: =AA15/24 -> 0.47346667 | AE15: =D15-AC15 -> 37.9198 | AG15: 7 | AH15: 9994 | AI15: B | AJ15: 38.5 | AL15: 9994 | AM15: 11.6156 | AN15: 1.5565 | AO15: 0.593 | AP15: =AM15/24 -> 0.48398333 | AQ15: =AJ15-AO15 -> 37.907 | AU15: 9994 | AV15: 11.7229 | AW15: 1.5709 | AX15: 0.5985 | AY15: =AV15/24 -> 0.48845417 | AZ15: =AJ15-AX15 -> 37.9015 | BD15: 9994 | BE15: 11.7351 | BF15: 1.5725 | BG15: 0.5991 | BH15: =BE15/24 -> 0.4889625 | BI15: =AJ15-BG15 -> 37.9009 | BN15: 9994 | BO15: 11.7804 | BP15: 1.5786 | BQ15: 0.6015 | BR15: =BO15/24 -> 0.49085 | BS15: =AJ15-BQ15 -> 37.8985 | BX15: 9994 | BY15: 11.8696 | BZ15: 1.5906 | CA15: 0.606 | CB15: =BY15/24 -> 0.49456667 | CC15: =AJ15-CA15 -> 37.894 | CG15: 5 | CH15: 9994 | CI15: 11.9463 | CJ15: 1.6009 | CK15: 0.6099 | CL15: =CI15/24 -> 0.4977625 | CM15: =AJ15-CK15 -> 37.8901 | CQ15: 5 | CR15: 9994 | CS15: 12.0428 | CT15: 1.6138 | CU15: 0.6149 | CV15: =CS15/24 -> 0.50178333 | CW15: =AJ15-CU15 -> 37.8851 | DA15: 5 | DB15: 9994 | DC15: 12.0523 | DD15: 1.6151 | DE15: 0.6153 | DF15: =DC15/24 -> 0.50217917 | DG15: =AJ15-DE15 -> 37.8847 | DK15: 5 | DL15: 9994 | DM15: 12.1624 | DN15: 1.6298 | DO15: 0.621 | DP15: =DM15/24 -> 0.50676667 | DQ15: =AJ15-DO15 -> 37.879 | DS15: =DM15-DC15 -> 0.1101 | DU15: 5 | DV15: 9994 | DW15: 12.231 | DX15: 1.639 | DY15: 0.6245 | DZ15: =DW15/24 -> 0.509625 | EA15: =AJ15-DY15 -> 37.8755 | EE15: 5 | EF15: 9994 | EG15: 12.3382 | EH15: 1.6534 | EI15: 0.6299 | EJ15: =EG15/24 -> 0.51409167 | EK15: =AJ15-EI15 -> 37.8701 | EM15: =EK15-EA15 -> -0.0054 | EO15: 5 | EP15: 9994 | EQ15: 12.5513 | ER15: 1.6819 | ES15: 0.6408 | ET15: =EQ15/24 -> 0.52297083 | EU15: =AJ15-ES15 -> 37.8592 | EY15: 5 | EZ15: 9994 | FA15: 12.6518 | FB15: 1.6954 | FC15: 0.6459 | FD15: =FA15/24 -> 0.52715833 | FE15: =AJ15-FC15 -> 37.8541 | FG15: =FE15-EU15 -> -0.0051 | FI15: 5 | FJ15: 9994 | FK15: 12.7857 | FL15: 1.7133 | FM15: 0.6528 | FN15: =FK15/24 -> 0.5327375 | FO15: =AJ15-FM15 -> 37.8472 | FP15: =FO15-FE15 -> -0.0069 | FS15: 5 | FT15: 9994 | FU15: 12.8133 | FV15: 1.717 | FW15: 0.6542 | FX15: =FU15/24 -> 0.5338875 | FY15: =AJ15-FW15 -> 37.8458 | FZ15: =FU15-FK15 -> 0.0276 | GC15: 5 | GD15: 9994 | GE15: 12.8815 | GF15: 1.7262 | GG15: 0.6577 | GH15: =GE15/24 -> 0.53672917 | GI15: =$AJ15-GG15 -> 37.8423 | GJ15: =GE15-FU15 -> 0.0682 | GM15: 5 | GN15: 9994 | GO15: 13.0259 | GP15: 1.7455 | GQ15: 0.665 | GR15: =GO15/24 -> 0.54274583 | GS15: =$AJ15-GQ15 -> 37.835 | GT15: =GO15-GE15 -> 0.1444 | GW15: 5 | GX15: 9994 | GY15: =VLOOKUP(GX15,Sheet3!$AJ$7:$AN$83,2,0) -> 13.2091 | GZ15: =VLOOKUP(GX15,Sheet3!$AJ$7:$AN$83,3,0) -> 1.7701 | HA15: =VLOOKUP(GX15,Sheet3!$AJ$7:$AN$83,4,0) -> 0.6744 | HB15: =GY15/24 -> 0.55037917 | HC15: =$AJ15-HA15 -> 37.8256 | HD15: =GY15-GO15 -> 0.1832 | HE15: =HA15-GQ15 -> 0.0094 | HH15: 5 | HI15: 9994 | HJ15: 13.283 | HK15: 1.78 | HL15: 0.6782 | HM15: =HJ15/24 -> 0.55345833 | HN15: =$AJ15-HL15 -> 37.8218 | HO15: =HJ15-GY15 -> 0.0739 | HR15: 5 | HS15: 9994 | HT15: 13.3312 | HU15: 1.7864 | HV15: 0.6806 | HW15: =HT15/24 -> 0.55546667 | HX15: =$AJ15-HV15 -> 37.8194 | HY15: =HT15-HJ15 -> 0.0482 | IB15: 5 | IC15: 9994 | ID15: 13.3521 | IE15: 1.7892 | IF15: 0.6817 | IG15: =ID15/24 -> 0.5563375 | IH15: =$AJ15-IF15 -> 37.8183 | II15: =ID15-HT15 -> 0.0209 | IL15: 5 | IM15: 9994 | IN15: 13.4619 | IO15: 1.8039 | IP15: 0.6873 | IQ15: =IN15/24 -> 0.5609125 | IR15: =$AJ15-IP15 -> 37.8127 | IS15: =IN15-ID15 -> 0.1098 | IV15: 5 | IW15: 9994 | IX15: 13.6102 | IY15: 1.8238 | IZ15: 0.6949 | JA15: =IX15/24 -> 0.56709167 | JB15: =$AJ15-IZ15 -> 37.8051 | JC15: =IX15-IN15 -> 0.1483 | JF15: 5 | JG15: 9994 | JH15: 13.6573 | JI15: 1.8301 | JJ15: 0.6973 | JK15: =JH15/24 -> 0.56905417 | JL15: =$AJ15-JJ15 -> 37.8027 | JM15: =JH15-IX15 -> 0.0471 | JP15: 5 | JQ15: 9994 | JR15: 13.6952 | JS15: 1.8352 | JT15: 0.6992 | JU15: =JR15/24 -> 0.57063333 | JV15: =$AJ15-JT15 -> 37.8008 | JW15: =JR15-JH15 -> 0.0379 | JZ15: 5 | KA15: 9994 | KB15: 13.784 | KC15: 1.8471 | KD15: 0.7037 | KE15: =KB15/24 -> 0.57433333 | KF15: =$AJ15-KD15 -> 37.7963 | KG15: =KB15-JR15 -> 0.0888 | KJ15: 5 | KK15: 9994 | KL15: 13.8137 | KM15: 1.8511 | KN15: 0.7053 | KO15: =KL15/24 -> 0.57557083 | KP15: =$AJ15-KN15 -> 37.7947 | KQ15: =KL15-KB15 -> 0.0297 | KT15: 5 | KU15: 9994 | KV15: 13.8449 | KW15: 1.8553 | KX15: 0.7069 | KY15: =KV15/24 -> 0.57687083 | KZ15: =$AJ15-KX15 -> 37.7931 | LA15: =KV15-KL15 -> 0.0312 | LD15: 5 | LE15: 9994 | LF15: 13.871 | LG15: 1.8588 | LH15: 0.7082 | LI15: =LF15/24 -> 0.57795833 | LJ15: =$AJ15-LH15 -> 37.7918 | LK15: =LF15-KV15 -> 0.0261 | LN15: 5 | LO15: 9994 | LP15: 13.9076 | LQ15: 1.8637 | LR15: 0.7101 | LS15: =LP15/24 -> 0.57948333 | LT15: =$AJ15-LR15 -> 37.7899 | LU15: =LP15-LF15 -> 0.0366 | LX15: 5 | LY15: 9994 | LZ15: 13.9488 | MA15: 1.8692 | MB15: 0.7122 | MC15: =LZ15/24 -> 0.5812 | MD15: =$AJ15-MB15 -> 37.7878 | ME15: =LZ15-LP15 -> 0.0412 | MH15: 5 | MI15: 9994 | MJ15: 13.9893 | MK15: 1.8746 | ML15: 0.7142 | MM15: =MJ15/24 -> 0.5828875 | MN15: =$AJ15-ML15 -> 37.7858 | MO15: =MJ15-LZ15 -> 0.0405 | MR15: 5 | MS15: 9994 | MT15: 14.0666 | MU15: 1.885 | MV15: 0.7182 | MW15: =MT15/24 -> 0.58610833 | MX15: =$AJ15-MV15 -> 37.7818 | MY15: =MT15-MJ15 -> 0.0773 | NB15: 5 | NC15: 9994 | ND15: 14.1456 | NE15: 1.8956 | NF15: 0.7222 | NG15: =ND15/24 -> 0.5894 | NH15: =$AJ15-NF15 -> 37.7778 | NI15: =ND15-MT15 -> 0.079 | NL15: 5 | NM15: 9994 | NN15: 14.1689 | NO15: 1.8987 | NP15: 0.7234 | NQ15: =NN15/24 -> 0.59037083 | NR15: =$AJ15-NP15 -> 37.7766 | NS15: =NN15-ND15 -> 0.0233 | NV15: 5 | NW15: 9994 | NX15: 14.2058 | NY15: 1.9036 | NZ15: 0.7253 | OA15: =NX15/24 -> 0.59190833 | OB15: =$AJ15-NZ15 -> 37.7747 | OC15: =NX15-NN15 -> 0.0369 | OF15: 5 | OG15: 9994 | OH15: 14.2243 | OI15: 1.9061 | OJ15: 0.7262 | OK15: =OH15/24 -> 0.59267917 | OL15: =$AJ15-OJ15 -> 37.7738 | OM15: =OH15-NX15 -> 0.0185 | OP15: 5 | OQ15: 9994 | OR15: =VLOOKUP(OQ15,Sheet4!A13:F89,3,0) -> 14.2667 | OS15: =VLOOKUP(OQ15,Sheet4!A13:F89,4,0) -> 1.9118 | OT15: =VLOOKUP(OQ15,Sheet4!A13:F89,5,0) -> 0.7284 | OU15: =OR15/24 -> 0.59444583 | OV15: =$AJ15-OT15 -> 37.7716 | OW15: =OR15-OH15 -> 0.0424
A16: 8 | B16: 9995 | C16: B | D16: 38.5 | J16: 9995 | K16: 11.0345 | L16: 1.4787 | M16: 0.5634 | N16: =K16/24 -> 0.45977083 | O16: =D16-M16 -> 37.9366 | R16: 9995 | S16: 11.1296 | T16: 1.4914 | U16: 0.5682 | V16: =S16/24 -> 0.46373333 | W16: =D16-U16 -> 37.9318 | Z16: 9995 | AA16: 11.3632 | AB16: 1.5227 | AC16: 0.5802 | AD16: =AA16/24 -> 0.47346667 | AE16: =D16-AC16 -> 37.9198 | AG16: 8 | AH16: 9995 | AI16: B | AJ16: 38.5 | AL16: 9995 | AM16: 11.6156 | AN16: 1.5565 | AO16: 0.593 | AP16: =AM16/24 -> 0.48398333 | AQ16: =AJ16-AO16 -> 37.907 | AU16: 9995 | AV16: 11.7229 | AW16: 1.5709 | AX16: 0.5985 | AY16: =AV16/24 -> 0.48845417 | AZ16: =AJ16-AX16 -> 37.9015 | BD16: 9995 | BE16: 11.7351 | BF16: 1.5725 | BG16: 0.5991 | BH16: =BE16/24 -> 0.4889625 | BI16: =AJ16-BG16 -> 37.9009 | BN16: 9995 | BO16: 11.7804 | BP16: 1.5786 | BQ16: 0.6015 | BR16: =BO16/24 -> 0.49085 | BS16: =AJ16-BQ16 -> 37.8985 | BX16: 9995 | BY16: 11.8696 | BZ16: 1.5906 | CA16: 0.606 | CB16: =BY16/24 -> 0.49456667 | CC16: =AJ16-CA16 -> 37.894 | CG16: 6 | CH16: 9995 | CI16: 11.9463 | CJ16: 1.6009 | CK16: 0.6099 | CL16: =CI16/24 -> 0.4977625 | CM16: =AJ16-CK16 -> 37.8901 | CQ16: 6 | CR16: 9995 | CS16: 12.0428 | CT16: 1.6138 | CU16: 0.6149 | CV16: =CS16/24 -> 0.50178333 | CW16: =AJ16-CU16 -> 37.8851 | DA16: 6 | DB16: 9995 | DC16: 12.0523 | DD16: 1.6151 | DE16: 0.6153 | DF16: =DC16/24 -> 0.50217917 | DG16: =AJ16-DE16 -> 37.8847 | DK16: 6 | DL16: 9995 | DM16: 12.1624 | DN16: 1.6298 | DO16: 0.621 | DP16: =DM16/24 -> 0.50676667 | DQ16: =AJ16-DO16 -> 37.879 | DS16: =DM16-DC16 -> 0.1101 | DU16: 6 | DV16: 9995 | DW16: 12.231 | DX16: 1.639 | DY16: 0.6245 | DZ16: =DW16/24 -> 0.509625 | EA16: =AJ16-DY16 -> 37.8755 | EE16: 6 | EF16: 9995 | EG16: 12.3382 | EH16: 1.6534 | EI16: 0.6299 | EJ16: =EG16/24 -> 0.51409167 | EK16: =AJ16-EI16 -> 37.8701 | EM16: =EK16-EA16 -> -0.0054 | EO16: 6 | EP16: 9995 | EQ16: 12.5513 | ER16: 1.6819 | ES16: 0.6408 | ET16: =EQ16/24 -> 0.52297083 | EU16: =AJ16-ES16 -> 37.8592 | EY16: 6 | EZ16: 9995 | FA16: 12.6518 | FB16: 1.6954 | FC16: 0.6459 | FD16: =FA16/24 -> 0.52715833 | FE16: =AJ16-FC16 -> 37.8541 | FG16: =FE16-EU16 -> -0.0051 | FI16: 6 | FJ16: 9995 | FK16: 12.7857 | FL16: 1.7133 | FM16: 0.6528 | FN16: =FK16/24 -> 0.5327375 | FO16: =AJ16-FM16 -> 37.8472 | FP16: =FO16-FE16 -> -0.0069 | FS16: 6 | FT16: 9995 | FU16: 12.8133 | FV16: 1.717 | FW16: 0.6542 | FX16: =FU16/24 -> 0.5338875 | FY16: =AJ16-FW16 -> 37.8458 | FZ16: =FU16-FK16 -> 0.0276 | GC16: 6 | GD16: 9995 | GE16: 12.8815 | GF16: 1.7262 | GG16: 0.6577 | GH16: =GE16/24 -> 0.53672917 | GI16: =$AJ16-GG16 -> 37.8423 | GJ16: =GE16-FU16 -> 0.0682 | GM16: 6 | GN16: 9995 | GO16: 13.0259 | GP16: 1.7455 | GQ16: 0.665 | GR16: =GO16/24 -> 0.54274583 | GS16: =$AJ16-GQ16 -> 37.835 | GT16: =GO16-GE16 -> 0.1444 | GW16: 6 | GX16: 9995 | GY16: =VLOOKUP(GX16,Sheet3!$AJ$7:$AN$83,2,0) -> 13.2091 | GZ16: =VLOOKUP(GX16,Sheet3!$AJ$7:$AN$83,3,0) -> 1.7701 | HA16: =VLOOKUP(GX16,Sheet3!$AJ$7:$AN$83,4,0) -> 0.6744 | HB16: =GY16/24 -> 0.55037917 | HC16: =$AJ16-HA16 -> 37.8256 | HD16: =GY16-GO16 -> 0.1832 | HE16: =HA16-GQ16 -> 0.0094 | HH16: 6 | HI16: 9995 | HJ16: 13.283 | HK16: 1.78 | HL16: 0.6782 | HM16: =HJ16/24 -> 0.55345833 | HN16: =$AJ16-HL16 -> 37.8218 | HO16: =HJ16-GY16 -> 0.0739 | HR16: 6 | HS16: 9995 | HT16: 13.3312 | HU16: 1.7864 | HV16: 0.6806 | HW16: =HT16/24 -> 0.55546667 | HX16: =$AJ16-HV16 -> 37.8194 | HY16: =HT16-HJ16 -> 0.0482 | IB16: 6 | IC16: 9995 | ID16: 13.3521 | IE16: 1.7892 | IF16: 0.6817 | IG16: =ID16/24 -> 0.5563375 | IH16: =$AJ16-IF16 -> 37.8183 | II16: =ID16-HT16 -> 0.0209 | IL16: 6 | IM16: 9995 | IN16: 13.4619 | IO16: 1.8039 | IP16: 0.6873 | IQ16: =IN16/24 -> 0.5609125 | IR16: =$AJ16-IP16 -> 37.8127 | IS16: =IN16-ID16 -> 0.1098 | IV16: 6 | IW16: 9995 | IX16: 13.6102 | IY16: 1.8238 | IZ16: 0.6949 | JA16: =IX16/24 -> 0.56709167 | JB16: =$AJ16-IZ16 -> 37.8051 | JC16: =IX16-IN16 -> 0.1483 | JF16: 6 | JG16: 9995 | JH16: 13.6573 | JI16: 1.8301 | JJ16: 0.6973 | JK16: =JH16/24 -> 0.56905417 | JL16: =$AJ16-JJ16 -> 37.8027 | JM16: =JH16-IX16 -> 0.0471 | JP16: 6 | JQ16: 9995 | JR16: 13.6952 | JS16: 1.8352 | JT16: 0.6992 | JU16: =JR16/24 -> 0.57063333 | JV16: =$AJ16-JT16 -> 37.8008 | JW16: =JR16-JH16 -> 0.0379 | JZ16: 6 | KA16: 9995 | KB16: 13.784 | KC16: 1.8471 | KD16: 0.7037 | KE16: =KB16/24 -> 0.57433333 | KF16: =$AJ16-KD16 -> 37.7963 | KG16: =KB16-JR16 -> 0.0888 | KJ16: 6 | KK16: 9995 | KL16: 13.8137 | KM16: 1.8511 | KN16: 0.7053 | KO16: =KL16/24 -> 0.57557083 | KP16: =$AJ16-KN16 -> 37.7947 | KQ16: =KL16-KB16 -> 0.0297 | KT16: 6 | KU16: 9995 | KV16: 13.8449 | KW16: 1.8553 | KX16: 0.7069 | KY16: =KV16/24 -> 0.57687083 | KZ16: =$AJ16-KX16 -> 37.7931 | LA16: =KV16-KL16 -> 0.0312 | LD16: 6 | LE16: 9995 | LF16: 13.871 | LG16: 1.8588 | LH16: 0.7082 | LI16: =LF16/24 -> 0.57795833 | LJ16: =$AJ16-LH16 -> 37.7918 | LK16: =LF16-KV16 -> 0.0261 | LN16: 6 | LO16: 9995 | LP16: 13.9076 | LQ16: 1.8637 | LR16: 0.7101 | LS16: =LP16/24 -> 0.57948333 | LT16: =$AJ16-LR16 -> 37.7899 | LU16: =LP16-LF16 -> 0.0366 | LX16: 6 | LY16: 9995 | LZ16: 13.9488 | MA16: 1.8692 | MB16: 0.7122 | MC16: =LZ16/24 -> 0.5812 | MD16: =$AJ16-MB16 -> 37.7878 | ME16: =LZ16-LP16 -> 0.0412 | MH16: 6 | MI16: 9995 | MJ16: 13.9893 | MK16: 1.8746 | ML16: 0.7142 | MM16: =MJ16/24 -> 0.5828875 | MN16: =$AJ16-ML16 -> 37.7858 | MO16: =MJ16-LZ16 -> 0.0405 | MR16: 6 | MS16: 9995 | MT16: 14.0666 | MU16: 1.885 | MV16: 0.7182 | MW16: =MT16/24 -> 0.58610833 | MX16: =$AJ16-MV16 -> 37.7818 | MY16: =MT16-MJ16 -> 0.0773 | NB16: 6 | NC16: 9995 | ND16: 14.1456 | NE16: 1.8956 | NF16: 0.7222 | NG16: =ND16/24 -> 0.5894 | NH16: =$AJ16-NF16 -> 37.7778 | NI16: =ND16-MT16 -> 0.079 | NL16: 6 | NM16: 9995 | NN16: 14.1689 | NO16: 1.8987 | NP16: 0.7234 | NQ16: =NN16/24 -> 0.59037083 | NR16: =$AJ16-NP16 -> 37.7766 | NS16: =NN16-ND16 -> 0.0233 | NV16: 6 | NW16: 9995 | NX16: 14.2058 | NY16: 1.9036 | NZ16: 0.7253 | OA16: =NX16/24 -> 0.59190833 | OB16: =$AJ16-NZ16 -> 37.7747 | OC16: =NX16-NN16 -> 0.0369 | OF16: 6 | OG16: 9995 | OH16: 14.2243 | OI16: 1.9061 | OJ16: 0.7262 | OK16: =OH16/24 -> 0.59267917 | OL16: =$AJ16-OJ16 -> 37.7738 | OM16: =OH16-NX16 -> 0.0185 | OP16: 6 | OQ16: 9995 | OR16: =VLOOKUP(OQ16,Sheet4!A14:F90,3,0) -> 14.2667 | OS16: =VLOOKUP(OQ16,Sheet4!A14:F90,4,0) -> 1.9118 | OT16: =VLOOKUP(OQ16,Sheet4!A14:F90,5,0) -> 0.7284 | OU16: =OR16/24 -> 0.59444583 | OV16: =$AJ16-OT16 -> 37.7716 | OW16: =OR16-OH16 -> 0.0424
A17: 9 | B17: 9892 | C17: B | D17: 38.03 | J17: 9892 | K17: 9.4783 | L17: 1.2701 | M17: 0.4839 | N17: =K17/24 -> 0.39492917 | O17: =D17-M17 -> 37.5461 | R17: 9892 | S17: 9.565 | T17: 1.2817 | U17: 0.4883 | V17: =S17/24 -> 0.39854167 | W17: =D17-U17 -> 37.5417 | Z17: 9892 | AA17: 9.7781 | AB17: 1.3103 | AC17: 0.4992 | AD17: =AA17/24 -> 0.40742083 | AE17: =D17-AC17 -> 37.5308 | AG17: 9 | AH17: 9892 | AI17: B | AJ17: 38.03 | AL17: 9892 | AM17: 10.009 | AN17: 1.3412 | AO17: 0.511 | AP17: =AM17/24 -> 0.41704167 | AQ17: =AJ17-AO17 -> 37.519 | AU17: 9892 | AV17: 10.1072 | AW17: 1.3544 | AX17: 0.516 | AY17: =AV17/24 -> 0.42113333 | AZ17: =AJ17-AX17 -> 37.514 | BD17: 9892 | BE17: 10.1183 | BF17: 1.3559 | BG17: 0.5166 | BH17: =BE17/24 -> 0.42159583 | BI17: =AJ17-BG17 -> 37.5134 | BN17: 9892 | BO17: 10.1597 | BP17: 1.3614 | BQ17: 0.5187 | BR17: =BO17/24 -> 0.42332083 | BS17: =AJ17-BQ17 -> 37.5113 | BX17: 9892 | BY17: 10.2413 | BZ17: 1.3724 | CA17: 0.5229 | CB17: =BY17/24 -> 0.42672083 | CC17: =AJ17-CA17 -> 37.5071 | CG17: 7 | CH17: 9892 | CI17: 10.3115 | CJ17: 1.3818 | CK17: 0.5265 | CL17: =CI17/24 -> 0.42964583 | CM17: =AJ17-CK17 -> 37.5035 | CQ17: 7 | CR17: 9892 | CS17: 10.3997 | CT17: 1.3936 | CU17: 0.531 | CV17: =CS17/24 -> 0.43332083 | CW17: =AJ17-CU17 -> 37.499 | DA17: 7 | DB17: 9892 | DC17: 10.4084 | DD17: 1.3948 | DE17: 0.5314 | DF17: =DC17/24 -> 0.43368333 | DG17: =AJ17-DE17 -> 37.4986 | DK17: 7 | DL17: 9892 | DM17: 10.5091 | DN17: 1.4083 | DO17: 0.5365 | DP17: =DM17/24 -> 0.43787917 | DQ17: =AJ17-DO17 -> 37.4935 | DS17: =DM17-DC17 -> 0.1007 | DU17: 7 | DV17: 9892 | DW17: 10.5719 | DX17: 1.4167 | DY17: 0.5398 | DZ17: =DW17/24 -> 0.44049583 | EA17: =AJ17-DY17 -> 37.4902 | EE17: 7 | EF17: 9892 | EG17: 10.6699 | EH17: 1.4298 | EI17: 0.5448 | EJ17: =EG17/24 -> 0.44457917 | EK17: =AJ17-EI17 -> 37.4852 | EM17: =EK17-EA17 -> -0.005 | EO17: 7 | EP17: 9892 | EQ17: 10.8648 | ER17: 1.4559 | ES17: 0.5547 | ET17: =EQ17/24 -> 0.4527 | EU17: =AJ17-ES17 -> 37.4753 | EY17: 7 | EZ17: 9892 | FA17: 10.9567 | FB17: 1.4682 | FC17: 0.5594 | FD17: =FA17/24 -> 0.45652917 | FE17: =AJ17-FC17 -> 37.4706 | FG17: =FE17-EU17 -> -0.0047 | FI17: 7 | FJ17: 9892 | FK17: 11.0791 | FL17: 1.4846 | FM17: 0.5656 | FN17: =FK17/24 -> 0.46162917 | FO17: =AJ17-FM17 -> 37.4644 | FP17: =FO17-FE17 -> -0.0062 | FS17: 7 | FT17: 9892 | FU17: 11.1043 | FV17: 1.488 | FW17: 0.5669 | FX17: =FU17/24 -> 0.46267917 | FY17: =AJ17-FW17 -> 37.4631 | FZ17: =FU17-FK17 -> 0.0252 | GC17: 7 | GD17: 9892 | GE17: 11.1666 | GF17: 1.4964 | GG17: 0.5701 | GH17: =GE17/24 -> 0.465275 | GI17: =$AJ17-GG17 -> 37.4599 | GJ17: =GE17-FU17 -> 0.0623 | GM17: 7 | GN17: 9892 | GO17: 11.2986 | GP17: 1.5141 | GQ17: 0.5769 | GR17: =GO17/24 -> 0.470775 | GS17: =$AJ17-GQ17 -> 37.4531 | GT17: =GO17-GE17 -> 0.132 | GW17: 7 | GX17: 9892 | GY17: =VLOOKUP(GX17,Sheet3!$AJ$7:$AN$83,2,0) -> 11.4662 | GZ17: =VLOOKUP(GX17,Sheet3!$AJ$7:$AN$83,3,0) -> 1.5365 | HA17: =VLOOKUP(GX17,Sheet3!$AJ$7:$AN$83,4,0) -> 0.5854 | HB17: =GY17/24 -> 0.47775833 | HC17: =$AJ17-HA17 -> 37.4446 | HD17: =GY17-GO17 -> 0.1676 | HE17: =HA17-GQ17 -> 0.0085 | HH17: 7 | HI17: 9892 | HJ17: 11.5338 | HK17: 1.5456 | HL17: 0.5889 | HM17: =HJ17/24 -> 0.480575 | HN17: =$AJ17-HL17 -> 37.4411 | HO17: =HJ17-GY17 -> 0.0676 | HR17: 7 | HS17: 9892 | HT17: 11.5779 | HU17: 1.5515 | HV17: 0.5911 | HW17: =HT17/24 -> 0.4824125 | HX17: =$AJ17-HV17 -> 37.4389 | HY17: =HT17-HJ17 -> 0.0441 | IB17: 7 | IC17: 9892 | ID17: 11.597 | IE17: 1.554 | IF17: 0.5921 | IG17: =ID17/24 -> 0.48320833 | IH17: =$AJ17-IF17 -> 37.4379 | II17: =ID17-HT17 -> 0.0191 | IL17: 7 | IM17: 9892 | IN17: 11.6974 | IO17: 1.5675 | IP17: 0.5972 | IQ17: =IN17/24 -> 0.48739167 | IR17: =$AJ17-IP17 -> 37.4328 | IS17: =IN17-ID17 -> 0.1004 | IV17: 7 | IW17: 9892 | IX17: 11.833 | IY17: 1.5857 | IZ17: 0.6041 | JA17: =IX17/24 -> 0.49304167 | JB17: =$AJ17-IZ17 -> 37.4259 | JC17: =IX17-IN17 -> 0.1356 | JF17: 7 | JG17: 9892 | JH17: 11.8761 | JI17: 1.5914 | JJ17: 0.6063 | JK17: =JH17/24 -> 0.4948375 | JL17: =$AJ17-JJ17 -> 37.4237 | JM17: =JH17-IX17 -> 0.0431 | JP17: 7 | JQ17: 9892 | JR17: 11.9108 | JS17: 1.5961 | JT17: 0.6081 | JU17: =JR17/24 -> 0.49628333 | JV17: =$AJ17-JT17 -> 37.4219 | JW17: =JR17-JH17 -> 0.0347 | JZ17: 7 | KA17: 9892 | KB17: 11.992 | KC17: 1.607 | KD17: 0.6123 | KE17: =KB17/24 -> 0.49966667 | KF17: =$AJ17-KD17 -> 37.4177 | KG17: =KB17-JR17 -> 0.0812 | KJ17: 7 | KK17: 9892 | KL17: 12.0191 | KM17: 1.6106 | KN17: 0.6136 | KO17: =KL17/24 -> 0.50079583 | KP17: =$AJ17-KN17 -> 37.4164 | KQ17: =KL17-KB17 -> 0.0271 | KT17: 7 | KU17: 9892 | KV17: 12.0476 | KW17: 1.6144 | KX17: 0.6151 | KY17: =KV17/24 -> 0.50198333 | KZ17: =$AJ17-KX17 -> 37.4149 | LA17: =KV17-KL17 -> 0.0285 | LD17: 7 | LE17: 9892 | LF17: 12.0715 | LG17: 1.6176 | LH17: 0.6163 | LI17: =LF17/24 -> 0.50297917 | LJ17: =$AJ17-LH17 -> 37.4137 | LK17: =LF17-KV17 -> 0.0239 | LN17: 7 | LO17: 9892 | LP17: 12.105 | LQ17: 1.6221 | LR17: 0.618 | LS17: =LP17/24 -> 0.504375 | LT17: =$AJ17-LR17 -> 37.412 | LU17: =LP17-LF17 -> 0.0335 | LX17: 7 | LY17: 9892 | LZ17: 12.1426 | MA17: 1.6272 | MB17: 0.6199 | MC17: =LZ17/24 -> 0.50594167 | MD17: =$AJ17-MB17 -> 37.4101 | ME17: =LZ17-LP17 -> 0.0376 | MH17: 7 | MI17: 9892 | MJ17: 12.1797 | MK17: 1.6321 | ML17: 0.6218 | MM17: =MJ17/24 -> 0.5074875 | MN17: =$AJ17-ML17 -> 37.4082 | MO17: =MJ17-LZ17 -> 0.0371 | MR17: 7 | MS17: 9892 | MT17: 12.2504 | MU17: 1.6416 | MV17: 0.6255 | MW17: =MT17/24 -> 0.51043333 | MX17: =$AJ17-MV17 -> 37.4045 | MY17: =MT17-MJ17 -> 0.0707 | NB17: 7 | NC17: 9892 | ND17: 12.3227 | NE17: 1.6513 | NF17: 0.6291 | NG17: =ND17/24 -> 0.51344583 | NH17: =$AJ17-NF17 -> 37.4009 | NI17: =ND17-MT17 -> 0.0723 | NL17: 7 | NM17: 9892 | NN17: 12.344 | NO17: 1.6541 | NP17: 0.6302 | NQ17: =NN17/24 -> 0.51433333 | NR17: =$AJ17-NP17 -> 37.3998 | NS17: =NN17-ND17 -> 0.0213 | NV17: 7 | NW17: 9892 | NX17: 12.3777 | NY17: 1.6587 | NZ17: 0.6319 | OA17: =NX17/24 -> 0.5157375 | OB17: =$AJ17-NZ17 -> 37.3981 | OC17: =NX17-NN17 -> 0.0337 | OF17: 7 | OG17: 9892 | OH17: 12.3946 | OI17: 1.6609 | OJ17: 0.6328 | OK17: =OH17/24 -> 0.51644167 | OL17: =$AJ17-OJ17 -> 37.3972 | OM17: =OH17-NX17 -> 0.0169 | OP17: 7 | OQ17: 9892 | OR17: =VLOOKUP(OQ17,Sheet4!A15:F91,3,0) -> 12.4334 | OS17: =VLOOKUP(OQ17,Sheet4!A15:F91,4,0) -> 1.6661 | OT17: =VLOOKUP(OQ17,Sheet4!A15:F91,5,0) -> 0.6348 | OU17: =OR17/24 -> 0.51805833 | OV17: =$AJ17-OT17 -> 37.3952 | OW17: =OR17-OH17 -> 0.0388
